Workbook

Sheet 1월
A1: 정비일 | B1: 차번 | C1: 차종 | D1: 등록일자 | E1: 예방정비 | F1: 일반정비 | G1: 사고수리 | H1: 검사 | I1: 엔진오일(L) | J1: 미션오일(L) | K1: 타이어_교체 | L1: 타이어_펑크 | M1: 명일_정비예정 | N1: 기타사항
A2: 46023 | B2: 1801 | C2: =IFERROR(VLOOKUP(B2,차량리스트!$A:$C,2,0),"") -> K5 | D2: =IFERROR(VLOOKUP(B2,차량리스트!$A:$C,3,0),"") -> 45966 | M2: m
A3: 46024 | B3: 1801 | C3: =IFERROR(VLOOKUP(B3,차량리스트!$A:$C,2,0),"") -> K5 | D3: =IFERROR(VLOOKUP(B3,차량리스트!$A:$C,3,0),"") -> 45966 | E3: ○ | I3: 2
A4: 46024 | B4: 1804 | C4: =IFERROR(VLOOKUP(B4,차량리스트!$A:$C,2,0),"") -> K5 | D4: =IFERROR(VLOOKUP(B4,차량리스트!$A:$C,3,0),"") -> 45873 | E4: ○ | I4: 2
A5: 46024 | B5: 1852 | C5: =IFERROR(VLOOKUP(B5,차량리스트!$A:$C,2,0),"") -> K5H | D5: =IFERROR(VLOOKUP(B5,차량리스트!$A:$C,3,0),"") -> 44655 | G5: □
A6: 46024 | B6: 1890 | C6: =IFERROR(VLOOKUP(B6,차량리스트!$A:$C,2,0),"") -> K5H | D6: =IFERROR(VLOOKUP(B6,차량리스트!$A:$C,3,0),"") -> 44636 | F6: △ | I6: 2
A7: 46024 | B7: 1902 | C7: =IFERROR(VLOOKUP(B7,차량리스트!$A:$C,2,0),"") -> 니로 | D7: =IFERROR(VLOOKUP(B7,차량리스트!$A:$C,3,0),"") -> 44756 | F7: △
A8: 46024 | B8: 1915 | C8: =IFERROR(VLOOKUP(B8,차량리스트!$A:$C,2,0),"") -> K5H | D8: =IFERROR(VLOOKUP(B8,차량리스트!$A:$C,3,0),"") -> 44316 | E8: ○
A9: 46024 | B9: 1883 | C9: =IFERROR(VLOOKUP(B9,차량리스트!$A:$C,2,0),"") -> K5 | D9: =IFERROR(VLOOKUP(B9,차량리스트!$A:$C,3,0),"") -> 45455 | H9: ! | K9: 1
A10: 46024 | B10: 1853 | C10: =IFERROR(VLOOKUP(B10,차량리스트!$A:$C,2,0),"") -> K5H | D10: =IFERROR(VLOOKUP(B10,차량리스트!$A:$C,3,0),"") -> 44609 | N10: 미션수리(대성오토입고)
A11: 46025 | B11: 1813 | C11: =IFERROR(VLOOKUP(B11,차량리스트!$A:$C,2,0),"") -> K5H | D11: =IFERROR(VLOOKUP(B11,차량리스트!$A:$C,3,0),"") -> 45166 | F11: △ | I11: 2
A12: 46025 | B12: 1895 | C12: =IFERROR(VLOOKUP(B12,차량리스트!$A:$C,2,0),"") -> K5H | D12: =IFERROR(VLOOKUP(B12,차량리스트!$A:$C,3,0),"") -> 44558 | L12: 1
A13: 46026 | B13: 1803 | C13: =IFERROR(VLOOKUP(B13,차량리스트!$A:$C,2,0),"") -> K5H | D13: =IFERROR(VLOOKUP(B13,차량리스트!$A:$C,3,0),"") -> 44566 | M13: m
A14: 46027 | B14: 1803 | C14: =IFERROR(VLOOKUP(B14,차량리스트!$A:$C,2,0),"") -> K5H | D14: =IFERROR(VLOOKUP(B14,차량리스트!$A:$C,3,0),"") -> 44566 | E14: ○ | I14: 3
A15: 46027 | B15: 1901 | C15: =IFERROR(VLOOKUP(B15,차량리스트!$A:$C,2,0),"") -> K5 | D15: =IFERROR(VLOOKUP(B15,차량리스트!$A:$C,3,0),"") -> 45477 | F15: △ | I15: 2
A16: 46027 | B16: 1904 | C16: =IFERROR(VLOOKUP(B16,차량리스트!$A:$C,2,0),"") -> K5 | D16: =IFERROR(VLOOKUP(B16,차량리스트!$A:$C,3,0),"") -> 45477 | G16: □
A17: 46027 | B17: 1911 | C17: =IFERROR(VLOOKUP(B17,차량리스트!$A:$C,2,0),"") -> 아닉 | D17: =IFERROR(VLOOKUP(B17,차량리스트!$A:$C,3,0),"") -> 45602 | F17: △
A18: 46027 | B18: 1807 | C18: =IFERROR(VLOOKUP(B18,차량리스트!$A:$C,2,0),"") -> K5H | D18: =IFERROR(VLOOKUP(B18,차량리스트!$A:$C,3,0),"") -> 44288 | M18: m
A19: 46027 | B19: 1813 | C19: =IFERROR(VLOOKUP(B19,차량리스트!$A:$C,2,0),"") -> K5H | D19: =IFERROR(VLOOKUP(B19,차량리스트!$A:$C,3,0),"") -> 45166 | J19: 3
A20: 46027 | B20: 1832 | C20: =IFERROR(VLOOKUP(B20,차량리스트!$A:$C,2,0),"") -> K5H | D20: =IFERROR(VLOOKUP(B20,차량리스트!$A:$C,3,0),"") -> 44609 | L20: 1
C21: =IFERROR(VLOOKUP(B21,차량리스트!$A:$C,2,0),"") | D21: =IFERROR(VLOOKUP(B21,차량리스트!$A:$C,3,0),"")
C22: =IFERROR(VLOOKUP(B22,차량리스트!$A:$C,2,0),"") | D22: =IFERROR(VLOOKUP(B22,차량리스트!$A:$C,3,0),"")
C23: =IFERROR(VLOOKUP(B23,차량리스트!$A:$C,2,0),"") | D23: =IFERROR(VLOOKUP(B23,차량리스트!$A:$C,3,0),"")
C24: =IFERROR(VLOOKUP(B24,차량리스트!$A:$C,2,0),"") | D24: =IFERROR(VLOOKUP(B24,차량리스트!$A:$C,3,0),"")
C25: =IFERROR(VLOOKUP(B25,차량리스트!$A:$C,2,0),"") | D25: =IFERROR(VLOOKUP(B25,차량리스트!$A:$C,3,0),"")
C26: =IFERROR(VLOOKUP(B26,차량리스트!$A:$C,2,0),"") | D26: =IFERROR(VLOOKUP(B26,차량리스트!$A:$C,3,0),"")
C27: =IFERROR(VLOOKUP(B27,차량리스트!$A:$C,2,0),"") | D27: =IFERROR(VLOOKUP(B27,차량리스트!$A:$C,3,0),"")
C28: =IFERROR(VLOOKUP(B28,차량리스트!$A:$C,2,0),"") | D28: =IFERROR(VLOOKUP(B28,차량리스트!$A:$C,3,0),"")
C29: =IFERROR(VLOOKUP(B29,차량리스트!$A:$C,2,0),"") | D29: =IFERROR(VLOOKUP(B29,차량리스트!$A:$C,3,0),"")
C30: =IFERROR(VLOOKUP(B30,차량리스트!$A:$C,2,0),"") | D30: =IFERROR(VLOOKUP(B30,차량리스트!$A:$C,3,0),"")
C31: =IFERROR(VLOOKUP(B31,차량리스트!$A:$C,2,0),"") | D31: =IFERROR(VLOOKUP(B31,차량리스트!$A:$C,3,0),"")
C32: =IFERROR(VLOOKUP(B32,차량리스트!$A:$C,2,0),"") | D32: =IFERROR(VLOOKUP(B32,차량리스트!$A:$C,3,0),"")
... C101: =IFERROR(VLOOKUP(B101,차량리스트!$A:$C,2,0),"") | D101: =IFERROR(VLOOKUP(B101,차량리스트!$A:$C,3,0),"")

Sheet 2월
A1: 정비일 | B1: 차번 | C1: 차종 | D1: 등록일자 | E1: 예방정비 | F1: 일반정비 | G1: 사고수리 | H1: 검사 | I1: 엔진오일(L) | J1: 미션오일(L) | K1: 타이어_교체 | L1: 타이어_펑크 | M1: 명일_정비예정 | N1: 기타사항
A2: 46054 | B2: 1801 | C2: =IFERROR(VLOOKUP(B2,차량리스트!$A:$C,2,0),"") -> K5 | D2: =IFERROR(VLOOKUP(B2,차량리스트!$A:$C,3,0),"") -> 45966 | M2: m
A3: 46054 | B3: 1803 | C3: =IFERROR(VLOOKUP(B3,차량리스트!$A:$C,2,0),"") -> K5H | D3: =IFERROR(VLOOKUP(B3,차량리스트!$A:$C,3,0),"") -> 44566 | M3: m
A4: 46054 | B4: 1804 | C4: =IFERROR(VLOOKUP(B4,차량리스트!$A:$C,2,0),"") -> K5 | D4: =IFERROR(VLOOKUP(B4,차량리스트!$A:$C,3,0),"") -> 45873 | M4: m
A5: 46055 | B5: 1804 | C5: =IFERROR(VLOOKUP(B5,차량리스트!$A:$C,2,0),"") -> K5 | D5: =IFERROR(VLOOKUP(B5,차량리스트!$A:$C,3,0),"") -> 45873 | E5: ○ | J5: 2
A6: 46055 | B6: 1828 | C6: =IFERROR(VLOOKUP(B6,차량리스트!$A:$C,2,0),"") -> K5H | D6: =IFERROR(VLOOKUP(B6,차량리스트!$A:$C,3,0),"") -> 44566 | F6: △
A7: 46055 | B7: 1840 | C7: =IFERROR(VLOOKUP(B7,차량리스트!$A:$C,2,0),"") -> K5 | D7: =IFERROR(VLOOKUP(B7,차량리스트!$A:$C,3,0),"") -> 45477 | F7: △ | K7: 1
A8: 46055 | B8: 1807 | C8: =IFERROR(VLOOKUP(B8,차량리스트!$A:$C,2,0),"") -> K5H | D8: =IFERROR(VLOOKUP(B8,차량리스트!$A:$C,3,0),"") -> 44288 | M8: m
A9: 46055 | B9: 1813 | C9: =IFERROR(VLOOKUP(B9,차량리스트!$A:$C,2,0),"") -> K5H | D9: =IFERROR(VLOOKUP(B9,차량리스트!$A:$C,3,0),"") -> 45166 | M9: m
A10: 46055 | B10: 1814 | C10: =IFERROR(VLOOKUP(B10,차량리스트!$A:$C,2,0),"") -> 쏘타 | D10: =IFERROR(VLOOKUP(B10,차량리스트!$A:$C,3,0),"") -> 45626 | M10: m
A11: 46055 | B11: 1880 | C11: =IFERROR(VLOOKUP(B11,차량리스트!$A:$C,2,0),"") -> 아닉 | D11: =IFERROR(VLOOKUP(B11,차량리스트!$A:$C,3,0),"") -> 45632 | E11: ○ | L11: 1
A12: 46056 | B12: 1801 | C12: =IFERROR(VLOOKUP(B12,차량리스트!$A:$C,2,0),"") -> K5 | D12: =IFERROR(VLOOKUP(B12,차량리스트!$A:$C,3,0),"") -> 45966 | E12: ○ | I12: 5
A13: 46056 | B13: 1813 | C13: =IFERROR(VLOOKUP(B13,차량리스트!$A:$C,2,0),"") -> K5H | D13: =IFERROR(VLOOKUP(B13,차량리스트!$A:$C,3,0),"") -> 45166 | E13: ○ | I13: 4
A14: 46056 | B14: 1871 | C14: =IFERROR(VLOOKUP(B14,차량리스트!$A:$C,2,0),"") -> 아닉 | D14: =IFERROR(VLOOKUP(B14,차량리스트!$A:$C,3,0),"") -> 45602 | F14: △ | K14: 1
A15: 46056 | B15: 1911 | C15: =IFERROR(VLOOKUP(B15,차량리스트!$A:$C,2,0),"") -> 아닉 | D15: =IFERROR(VLOOKUP(B15,차량리스트!$A:$C,3,0),"") -> 45602 | F15: △
A16: 46056 | B16: 1815 | C16: =IFERROR(VLOOKUP(B16,차량리스트!$A:$C,2,0),"") -> 쏘타 | D16: =IFERROR(VLOOKUP(B16,차량리스트!$A:$C,3,0),"") -> 45626 | M16: m
A17: 46056 | B17: 1819 | C17: =IFERROR(VLOOKUP(B17,차량리스트!$A:$C,2,0),"") -> K5 | D17: =IFERROR(VLOOKUP(B17,차량리스트!$A:$C,3,0),"") -> 45873 | M17: m
A18: 46056 | B18: 1823 | C18: =IFERROR(VLOOKUP(B18,차량리스트!$A:$C,2,0),"") -> K5 | D18: =IFERROR(VLOOKUP(B18,차량리스트!$A:$C,3,0),"") -> 45455 | M18: m
A19: 46057 | B19: 1823 | C19: =IFERROR(VLOOKUP(B19,차량리스트!$A:$C,2,0),"") -> K5 | D19: =IFERROR(VLOOKUP(B19,차량리스트!$A:$C,3,0),"") -> 45455 | F19: △ | I19: 2
A20: 46057 | B20: 1857 | C20: =IFERROR(VLOOKUP(B20,차량리스트!$A:$C,2,0),"") -> K5 | D20: =IFERROR(VLOOKUP(B20,차량리스트!$A:$C,3,0),"") -> 45904 | F20: △
A21: 46057 | B21: 1898 | C21: =IFERROR(VLOOKUP(B21,차량리스트!$A:$C,2,0),"") -> 아닉 | D21: =IFERROR(VLOOKUP(B21,차량리스트!$A:$C,3,0),"") -> 45547 | F21: △ | G21: □
A22: 46057 | B22: 1825 | C22: =IFERROR(VLOOKUP(B22,차량리스트!$A:$C,2,0),"") -> 쏘타 | D22: =IFERROR(VLOOKUP(B22,차량리스트!$A:$C,3,0),"") -> 45626 | M22: m
A23: 46057 | B23: 1828 | C23: =IFERROR(VLOOKUP(B23,차량리스트!$A:$C,2,0),"") -> K5H | D23: =IFERROR(VLOOKUP(B23,차량리스트!$A:$C,3,0),"") -> 44566 | M23: m
A24: 46057 | B24: 1830 | C24: =IFERROR(VLOOKUP(B24,차량리스트!$A:$C,2,0),"") -> K5 | D24: =IFERROR(VLOOKUP(B24,차량리스트!$A:$C,3,0),"") -> 45966 | M24: m
C25: =IFERROR(VLOOKUP(B25,차량리스트!$A:$C,2,0),"") | D25: =IFERROR(VLOOKUP(B25,차량리스트!$A:$C,3,0),"")
C26: =IFERROR(VLOOKUP(B26,차량리스트!$A:$C,2,0),"") | D26: =IFERROR(VLOOKUP(B26,차량리스트!$A:$C,3,0),"")
C27: =IFERROR(VLOOKUP(B27,차량리스트!$A:$C,2,0),"") | D27: =IFERROR(VLOOKUP(B27,차량리스트!$A:$C,3,0),"")
C28: =IFERROR(VLOOKUP(B28,차량리스트!$A:$C,2,0),"") | D28: =IFERROR(VLOOKUP(B28,차량리스트!$A:$C,3,0),"")
C29: =IFERROR(VLOOKUP(B29,차량리스트!$A:$C,2,0),"") | D29: =IFERROR(VLOOKUP(B29,차량리스트!$A:$C,3,0),"")
C30: =IFERROR(VLOOKUP(B30,차량리스트!$A:$C,2,0),"") | D30: =IFERROR(VLOOKUP(B30,차량리스트!$A:$C,3,0),"")
C31: =IFERROR(VLOOKUP(B31,차량리스트!$A:$C,2,0),"") | D31: =IFERROR(VLOOKUP(B31,차량리스트!$A:$C,3,0),"")
C32: =IFERROR(VLOOKUP(B32,차량리스트!$A:$C,2,0),"") | D32: =IFERROR(VLOOKUP(B32,차량리스트!$A:$C,3,0),"")
C33: =IFERROR(VLOOKUP(B33,차량리스트!$A:$C,2,0),"") | D33: =IFERROR(VLOOKUP(B33,차량리스트!$A:$C,3,0),"")
C34: =IFERROR(VLOOKUP(B34,차량리스트!$A:$C,2,0),"") | D34: =IFERROR(VLOOKUP(B34,차량리스트!$A:$C,3,0),"")
C35: =IFERROR(VLOOKUP(B35,차량리스트!$A:$C,2,0),"") | D35: =IFERROR(VLOOKUP(B35,차량리스트!$A:$C,3,0),"")
C36: =IFERROR(VLOOKUP(B36,차량리스트!$A:$C,2,0),"") | D36: =IFERROR(VLOOKUP(B36,차량리스트!$A:$C,3,0),"")
... C101: =IFERROR(VLOOKUP(B101,차량리스트!$A:$C,2,0),"") | D101: =IFERROR(VLOOKUP(B101,차량리스트!$A:$C,3,0),"")

Sheet 3월
A1: 정비일 | B1: 차번 | C1: 차종 | D1: 등록일자 | E1: 예방정비 | F1: 일반정비 | G1: 사고수리 | H1: 검사 | I1: 엔진오일(L) | J1: 미션오일(L) | K1: 타이어_교체 | L1: 타이어_펑크 | M1: 명일_정비예정 | N1: 기타사항
C2: =IFERROR(VLOOKUP(B2,차량리스트!$A:$C,2,0),"") | D2: =IFERROR(VLOOKUP(B2,차량리스트!$A:$C,3,0),"")
C3: =IFERROR(VLOOKUP(B3,차량리스트!$A:$C,2,0),"") | D3: =IFERROR(VLOOKUP(B3,차량리스트!$A:$C,3,0),"")
C4: =IFERROR(VLOOKUP(B4,차량리스트!$A:$C,2,0),"") | D4: =IFERROR(VLOOKUP(B4,차량리스트!$A:$C,3,0),"")
C5: =IFERROR(VLOOKUP(B5,차량리스트!$A:$C,2,0),"") | D5: =IFERROR(VLOOKUP(B5,차량리스트!$A:$C,3,0),"")
C6: =IFERROR(VLOOKUP(B6,차량리스트!$A:$C,2,0),"") | D6: =IFERROR(VLOOKUP(B6,차량리스트!$A:$C,3,0),"")
C7: =IFERROR(VLOOKUP(B7,차량리스트!$A:$C,2,0),"") | D7: =IFERROR(VLOOKUP(B7,차량리스트!$A:$C,3,0),"")
C8: =IFERROR(VLOOKUP(B8,차량리스트!$A:$C,2,0),"") | D8: =IFERROR(VLOOKUP(B8,차량리스트!$A:$C,3,0),"")
C9: =IFERROR(VLOOKUP(B9,차량리스트!$A:$C,2,0),"") | D9: =IFERROR(VLOOKUP(B9,차량리스트!$A:$C,3,0),"")
C10: =IFERROR(VLOOKUP(B10,차량리스트!$A:$C,2,0),"") | D10: =IFERROR(VLOOKUP(B10,차량리스트!$A:$C,3,0),"")
C11: =IFERROR(VLOOKUP(B11,차량리스트!$A:$C,2,0),"") | D11: =IFERROR(VLOOKUP(B11,차량리스트!$A:$C,3,0),"")
C12: =IFERROR(VLOOKUP(B12,차량리스트!$A:$C,2,0),"") | D12: =IFERROR(VLOOKUP(B12,차량리스트!$A:$C,3,0),"")
C13: =IFERROR(VLOOKUP(B13,차량리스트!$A:$C,2,0),"") | D13: =IFERROR(VLOOKUP(B13,차량리스트!$A:$C,3,0),"")
... C101: =IFERROR(VLOOKUP(B101,차량리스트!$A:$C,2,0),"") | D101: =IFERROR(VLOOKUP(B101,차량리스트!$A:$C,3,0),"")

Sheet 4월
A1: 정비일 | B1: 차번 | C1: 차종 | D1: 등록일자 | E1: 예방정비 | F1: 일반정비 | G1: 사고수리 | H1: 검사 | I1: 엔진오일(L) | J1: 미션오일(L) | K1: 타이어_교체 | L1: 타이어_펑크 | M1: 명일_정비예정 | N1: 기타사항
C2: =IFERROR(VLOOKUP(B2,차량리스트!$A:$C,2,0),"") | D2: =IFERROR(VLOOKUP(B2,차량리스트!$A:$C,3,0),"")
C3: =IFERROR(VLOOKUP(B3,차량리스트!$A:$C,2,0),"") | D3: =IFERROR(VLOOKUP(B3,차량리스트!$A:$C,3,0),"")
C4: =IFERROR(VLOOKUP(B4,차량리스트!$A:$C,2,0),"") | D4: =IFERROR(VLOOKUP(B4,차량리스트!$A:$C,3,0),"")
C5: =IFERROR(VLOOKUP(B5,차량리스트!$A:$C,2,0),"") | D5: =IFERROR(VLOOKUP(B5,차량리스트!$A:$C,3,0),"")
C6: =IFERROR(VLOOKUP(B6,차량리스트!$A:$C,2,0),"") | D6: =IFERROR(VLOOKUP(B6,차량리스트!$A:$C,3,0),"")
C7: =IFERROR(VLOOKUP(B7,차량리스트!$A:$C,2,0),"") | D7: =IFERROR(VLOOKUP(B7,차량리스트!$A:$C,3,0),"")
C8: =IFERROR(VLOOKUP(B8,차량리스트!$A:$C,2,0),"") | D8: =IFERROR(VLOOKUP(B8,차량리스트!$A:$C,3,0),"")
C9: =IFERROR(VLOOKUP(B9,차량리스트!$A:$C,2,0),"") | D9: =IFERROR(VLOOKUP(B9,차량리스트!$A:$C,3,0),"")
C10: =IFERROR(VLOOKUP(B10,차량리스트!$A:$C,2,0),"") | D10: =IFERROR(VLOOKUP(B10,차량리스트!$A:$C,3,0),"")
C11: =IFERROR(VLOOKUP(B11,차량리스트!$A:$C,2,0),"") | D11: =IFERROR(VLOOKUP(B11,차량리스트!$A:$C,3,0),"")
C12: =IFERROR(VLOOKUP(B12,차량리스트!$A:$C,2,0),"") | D12: =IFERROR(VLOOKUP(B12,차량리스트!$A:$C,3,0),"")
C13: =IFERROR(VLOOKUP(B13,차량리스트!$A:$C,2,0),"") | D13: =IFERROR(VLOOKUP(B13,차량리스트!$A:$C,3,0),"")
... C101: =IFERROR(VLOOKUP(B101,차량리스트!$A:$C,2,0),"") | D101: =IFERROR(VLOOKUP(B101,차량리스트!$A:$C,3,0),"")

Sheet 5월
A1: 정비일 | B1: 차번 | C1: 차종 | D1: 등록일자 | E1: 예방정비 | F1: 일반정비 | G1: 사고수리 | H1: 검사 | I1: 엔진오일(L) | J1: 미션오일(L) | K1: 타이어_교체 | L1: 타이어_펑크 | M1: 명일_정비예정 | N1: 기타사항
C2: =IFERROR(VLOOKUP(B2,차량리스트!$A:$C,2,0),"") | D2: =IFERROR(VLOOKUP(B2,차량리스트!$A:$C,3,0),"")
C3: =IFERROR(VLOOKUP(B3,차량리스트!$A:$C,2,0),"") | D3: =IFERROR(VLOOKUP(B3,차량리스트!$A:$C,3,0),"")
C4: =IFERROR(VLOOKUP(B4,차량리스트!$A:$C,2,0),"") | D4: =IFERROR(VLOOKUP(B4,차량리스트!$A:$C,3,0),"")
C5: =IFERROR(VLOOKUP(B5,차량리스트!$A:$C,2,0),"") | D5: =IFERROR(VLOOKUP(B5,차량리스트!$A:$C,3,0),"")
C6: =IFERROR(VLOOKUP(B6,차량리스트!$A:$C,2,0),"") | D6: =IFERROR(VLOOKUP(B6,차량리스트!$A:$C,3,0),"")
C7: =IFERROR(VLOOKUP(B7,차량리스트!$A:$C,2,0),"") | D7: =IFERROR(VLOOKUP(B7,차량리스트!$A:$C,3,0),"")
C8: =IFERROR(VLOOKUP(B8,차량리스트!$A:$C,2,0),"") | D8: =IFERROR(VLOOKUP(B8,차량리스트!$A:$C,3,0),"")
C9: =IFERROR(VLOOKUP(B9,차량리스트!$A:$C,2,0),"") | D9: =IFERROR(VLOOKUP(B9,차량리스트!$A:$C,3,0),"")
C10: =IFERROR(VLOOKUP(B10,차량리스트!$A:$C,2,0),"") | D10: =IFERROR(VLOOKUP(B10,차량리스트!$A:$C,3,0),"")
C11: =IFERROR(VLOOKUP(B11,차량리스트!$A:$C,2,0),"") | D11: =IFERROR(VLOOKUP(B11,차량리스트!$A:$C,3,0),"")
C12: =IFERROR(VLOOKUP(B12,차량리스트!$A:$C,2,0),"") | D12: =IFERROR(VLOOKUP(B12,차량리스트!$A:$C,3,0),"")
C13: =IFERROR(VLOOKUP(B13,차량리스트!$A:$C,2,0),"") | D13: =IFERROR(VLOOKUP(B13,차량리스트!$A:$C,3,0),"")
... C101: =IFERROR(VLOOKUP(B101,차량리스트!$A:$C,2,0),"") | D101: =IFERROR(VLOOKUP(B101,차량리스트!$A:$C,3,0),"")

Sheet 6월
A1: 정비일 | B1: 차번 | C1: 차종 | D1: 등록일자 | E1: 예방정비 | F1: 일반정비 | G1: 사고수리 | H1: 검사 | I1: 엔진오일(L) | J1: 미션오일(L) | K1: 타이어_교체 | L1: 타이어_펑크 | M1: 명일_정비예정 | N1: 기타사항
C2: =IFERROR(VLOOKUP(B2,차량리스트!$A:$C,2,0),"") | D2: =IFERROR(VLOOKUP(B2,차량리스트!$A:$C,3,0),"")
C3: =IFERROR(VLOOKUP(B3,차량리스트!$A:$C,2,0),"") | D3: =IFERROR(VLOOKUP(B3,차량리스트!$A:$C,3,0),"")
C4: =IFERROR(VLOOKUP(B4,차량리스트!$A:$C,2,0),"") | D4: =IFERROR(VLOOKUP(B4,차량리스트!$A:$C,3,0),"")
C5: =IFERROR(VLOOKUP(B5,차량리스트!$A:$C,2,0),"") | D5: =IFERROR(VLOOKUP(B5,차량리스트!$A:$C,3,0),"")
C6: =IFERROR(VLOOKUP(B6,차량리스트!$A:$C,2,0),"") | D6: =IFERROR(VLOOKUP(B6,차량리스트!$A:$C,3,0),"")
C7: =IFERROR(VLOOKUP(B7,차량리스트!$A:$C,2,0),"") | D7: =IFERROR(VLOOKUP(B7,차량리스트!$A:$C,3,0),"")
C8: =IFERROR(VLOOKUP(B8,차량리스트!$A:$C,2,0),"") | D8: =IFERROR(VLOOKUP(B8,차량리스트!$A:$C,3,0),"")
C9: =IFERROR(VLOOKUP(B9,차량리스트!$A:$C,2,0),"") | D9: =IFERROR(VLOOKUP(B9,차량리스트!$A:$C,3,0),"")
C10: =IFERROR(VLOOKUP(B10,차량리스트!$A:$C,2,0),"") | D10: =IFERROR(VLOOKUP(B10,차량리스트!$A:$C,3,0),"")
C11: =IFERROR(VLOOKUP(B11,차량리스트!$A:$C,2,0),"") | D11: =IFERROR(VLOOKUP(B11,차량리스트!$A:$C,3,0),"")
C12: =IFERROR(VLOOKUP(B12,차량리스트!$A:$C,2,0),"") | D12: =IFERROR(VLOOKUP(B12,차량리스트!$A:$C,3,0),"")
C13: =IFERROR(VLOOKUP(B13,차량리스트!$A:$C,2,0),"") | D13: =IFERROR(VLOOKUP(B13,차량리스트!$A:$C,3,0),"")
... C101: =IFERROR(VLOOKUP(B101,차량리스트!$A:$C,2,0),"") | D101: =IFERROR(VLOOKUP(B101,차량리스트!$A:$C,3,0),"")

Sheet 7월
A1: 정비일 | B1: 차번 | C1: 차종 | D1: 등록일자 | E1: 예방정비 | F1: 일반정비 | G1: 사고수리 | H1: 검사 | I1: 엔진오일(L) | J1: 미션오일(L) | K1: 타이어_교체 | L1: 타이어_펑크 | M1: 명일_정비예정 | N1: 기타사항
C2: =IFERROR(VLOOKUP(B2,차량리스트!$A:$C,2,0),"") | D2: =IFERROR(VLOOKUP(B2,차량리스트!$A:$C,3,0),"")
C3: =IFERROR(VLOOKUP(B3,차량리스트!$A:$C,2,0),"") | D3: =IFERROR(VLOOKUP(B3,차량리스트!$A:$C,3,0),"")
C4: =IFERROR(VLOOKUP(B4,차량리스트!$A:$C,2,0),"") | D4: =IFERROR(VLOOKUP(B4,차량리스트!$A:$C,3,0),"")
C5: =IFERROR(VLOOKUP(B5,차량리스트!$A:$C,2,0),"") | D5: =IFERROR(VLOOKUP(B5,차량리스트!$A:$C,3,0),"")
C6: =IFERROR(VLOOKUP(B6,차량리스트!$A:$C,2,0),"") | D6: =IFERROR(VLOOKUP(B6,차량리스트!$A:$C,3,0),"")
C7: =IFERROR(VLOOKUP(B7,차량리스트!$A:$C,2,0),"") | D7: =IFERROR(VLOOKUP(B7,차량리스트!$A:$C,3,0),"")
C8: =IFERROR(VLOOKUP(B8,차량리스트!$A:$C,2,0),"") | D8: =IFERROR(VLOOKUP(B8,차량리스트!$A:$C,3,0),"")
C9: =IFERROR(VLOOKUP(B9,차량리스트!$A:$C,2,0),"") | D9: =IFERROR(VLOOKUP(B9,차량리스트!$A:$C,3,0),"")
C10: =IFERROR(VLOOKUP(B10,차량리스트!$A:$C,2,0),"") | D10: =IFERROR(VLOOKUP(B10,차량리스트!$A:$C,3,0),"")
C11: =IFERROR(VLOOKUP(B11,차량리스트!$A:$C,2,0),"") | D11: =IFERROR(VLOOKUP(B11,차량리스트!$A:$C,3,0),"")
C12: =IFERROR(VLOOKUP(B12,차량리스트!$A:$C,2,0),"") | D12: =IFERROR(VLOOKUP(B12,차량리스트!$A:$C,3,0),"")
C13: =IFERROR(VLOOKUP(B13,차량리스트!$A:$C,2,0),"") | D13: =IFERROR(VLOOKUP(B13,차량리스트!$A:$C,3,0),"")
... C101: =IFERROR(VLOOKUP(B101,차량리스트!$A:$C,2,0),"") | D101: =IFERROR(VLOOKUP(B101,차량리스트!$A:$C,3,0),"")

Sheet 8월
A1: 정비일 | B1: 차번 | C1: 차종 | D1: 등록일자 | E1: 예방정비 | F1: 일반정비 | G1: 사고수리 | H1: 검사 | I1: 엔진오일(L) | J1: 미션오일(L) | K1: 타이어_교체 | L1: 타이어_펑크 | M1: 명일_정비예정 | N1: 기타사항
A2: 46235 | C2: =IFERROR(VLOOKUP(B2,차량리스트!$A:$C,2,0),"") | D2: =IFERROR(VLOOKUP(B2,차량리스트!$A:$C,3,0),"") | I2: 2
A3: 46236 | B3: 1801 | C3: =IFERROR(VLOOKUP(B3,차량리스트!$A:$C,2,0),"") -> K5 | D3: =IFERROR(VLOOKUP(B3,차량리스트!$A:$C,3,0),"") -> 45966 | M3: m
A4: 46236 | B4: 1803 | C4: =IFERROR(VLOOKUP(B4,차량리스트!$A:$C,2,0),"") -> K5H | D4: =IFERROR(VLOOKUP(B4,차량리스트!$A:$C,3,0),"") -> 44566 | M4: m
A5: 46237 | B5: 1801 | C5: =IFERROR(VLOOKUP(B5,차량리스트!$A:$C,2,0),"") -> K5 | D5: =IFERROR(VLOOKUP(B5,차량리스트!$A:$C,3,0),"") -> 45966 | E5: O | I5: 2
A6: 46237 | B6: 1890 | C6: =IFERROR(VLOOKUP(B6,차량리스트!$A:$C,2,0),"") -> K5H | D6: =IFERROR(VLOOKUP(B6,차량리스트!$A:$C,3,0),"") -> 44636 | E6: O | N6: 예방정비(7/23)
A7: 46237 | B7: 1804 | C7: =IFERROR(VLOOKUP(B7,차량리스트!$A:$C,2,0),"") -> K5 | D7: =IFERROR(VLOOKUP(B7,차량리스트!$A:$C,3,0),"") -> 45873 | M7: m
A8: 46237 | B8: 1813 | C8: =IFERROR(VLOOKUP(B8,차량리스트!$A:$C,2,0),"") -> K5H | D8: =IFERROR(VLOOKUP(B8,차량리스트!$A:$C,3,0),"") -> 45166 | M8: m
A9: 46237 | B9: 1880 | C9: =IFERROR(VLOOKUP(B9,차량리스트!$A:$C,2,0),"") -> 아닉 | D9: =IFERROR(VLOOKUP(B9,차량리스트!$A:$C,3,0),"") -> 45632 | N9: 리콜A/S(현대당산점)
A10: 46238 | B10: 1804 | C10: =IFERROR(VLOOKUP(B10,차량리스트!$A:$C,2,0),"") -> K5 | D10: =IFERROR(VLOOKUP(B10,차량리스트!$A:$C,3,0),"") -> 45873 | E10: O | I10: 2
A11: 46238 | B11: 1813 | C11: =IFERROR(VLOOKUP(B11,차량리스트!$A:$C,2,0),"") -> K5H | D11: =IFERROR(VLOOKUP(B11,차량리스트!$A:$C,3,0),"") -> 45166 | E11: O
A12: 46238 | B12: 1840 | C12: =IFERROR(VLOOKUP(B12,차량리스트!$A:$C,2,0),"") -> K5 | D12: =IFERROR(VLOOKUP(B12,차량리스트!$A:$C,3,0),"") -> 45477 | F12: △
A13: 46238 | B13: 1868 | C13: =IFERROR(VLOOKUP(B13,차량리스트!$A:$C,2,0),"") -> K5H | D13: =IFERROR(VLOOKUP(B13,차량리스트!$A:$C,3,0),"") -> 45216 | G13: □
A14: 46238 | B14: 1833 | C14: =IFERROR(VLOOKUP(B14,차량리스트!$A:$C,2,0),"") -> K5 | D14: =IFERROR(VLOOKUP(B14,차량리스트!$A:$C,3,0),"") -> 45904 | K14: 1
A15: 46238 | B15: 1814 | C15: =IFERROR(VLOOKUP(B15,차량리스트!$A:$C,2,0),"") -> 쏘타 | D15: =IFERROR(VLOOKUP(B15,차량리스트!$A:$C,3,0),"") -> 45626 | M15: m
A16: 46238 | B16: 1815 | C16: =IFERROR(VLOOKUP(B16,차량리스트!$A:$C,2,0),"") -> 쏘타 | D16: =IFERROR(VLOOKUP(B16,차량리스트!$A:$C,3,0),"") -> 45626 | M16: m
A17: 46238 | B17: 1902 | C17: =IFERROR(VLOOKUP(B17,차량리스트!$A:$C,2,0),"") -> 니로 | D17: =IFERROR(VLOOKUP(B17,차량리스트!$A:$C,3,0),"") -> 44756 | N17: 타이어파스, 서교동출장수리
A18: 46239 | B18: 1819 | C18: =IFERROR(VLOOKUP(B18,차량리스트!$A:$C,2,0),"") -> K5 | D18: =IFERROR(VLOOKUP(B18,차량리스트!$A:$C,3,0),"") -> 45873 | E18: O | N18: 예방정비(8/06)
A19: 46239 | B19: 1812 | C19: =IFERROR(VLOOKUP(B19,차량리스트!$A:$C,2,0),"") -> 아닉 | D19: =IFERROR(VLOOKUP(B19,차량리스트!$A:$C,3,0),"") -> 45594 | F19: △ | I19: 2
A20: 46239 | B20: 1826 | C20: =IFERROR(VLOOKUP(B20,차량리스트!$A:$C,2,0),"") -> 니로 | D20: =IFERROR(VLOOKUP(B20,차량리스트!$A:$C,3,0),"") -> 44802 | F20: △
A21: 46239 | B21: 1835 | C21: =IFERROR(VLOOKUP(B21,차량리스트!$A:$C,2,0),"") -> 아닉 | D21: =IFERROR(VLOOKUP(B21,차량리스트!$A:$C,3,0),"") -> 45547 | F21: △
A22: 46239 | B22: 1826 | C22: =IFERROR(VLOOKUP(B22,차량리스트!$A:$C,2,0),"") -> 니로 | D22: =IFERROR(VLOOKUP(B22,차량리스트!$A:$C,3,0),"") -> 44802 | K22: 1
A23: 46239 | B23: 1835 | C23: =IFERROR(VLOOKUP(B23,차량리스트!$A:$C,2,0),"") -> 아닉 | D23: =IFERROR(VLOOKUP(B23,차량리스트!$A:$C,3,0),"") -> 45547 | K23: 1
A24: 46239 | B24: 1825 | C24: =IFERROR(VLOOKUP(B24,차량리스트!$A:$C,2,0),"") -> 쏘타 | D24: =IFERROR(VLOOKUP(B24,차량리스트!$A:$C,3,0),"") -> 45626 | M24: m
A25: 46240 | B25: 1803 | C25: =IFERROR(VLOOKUP(B25,차량리스트!$A:$C,2,0),"") -> K5H | D25: =IFERROR(VLOOKUP(B25,차량리스트!$A:$C,3,0),"") -> 44566 | E25: O | I25: 2 | N25: 예방정비(8/03)
A26: 46240 | B26: 1815 | C26: =IFERROR(VLOOKUP(B26,차량리스트!$A:$C,2,0),"") -> 쏘타 | D26: =IFERROR(VLOOKUP(B26,차량리스트!$A:$C,3,0),"") -> 45626 | E26: O | N26: 예방정비(8/05)
A27: 46240 | B27: 1825 | C27: =IFERROR(VLOOKUP(B27,차량리스트!$A:$C,2,0),"") -> 쏘타 | D27: =IFERROR(VLOOKUP(B27,차량리스트!$A:$C,3,0),"") -> 45626 | E27: O
A28: 46240 | B28: 1868 | C28: =IFERROR(VLOOKUP(B28,차량리스트!$A:$C,2,0),"") -> K5H | D28: =IFERROR(VLOOKUP(B28,차량리스트!$A:$C,3,0),"") -> 45216 | F28: △
A29: 46240 | B29: 1888 | C29: =IFERROR(VLOOKUP(B29,차량리스트!$A:$C,2,0),"") -> K5 | D29: =IFERROR(VLOOKUP(B29,차량리스트!$A:$C,3,0),"") -> 45974 | F29: △
A30: 46240 | B30: 1813 | C30: =IFERROR(VLOOKUP(B30,차량리스트!$A:$C,2,0),"") -> K5H | D30: =IFERROR(VLOOKUP(B30,차량리스트!$A:$C,3,0),"") -> 45166 | G30: □
A31: 46240 | B31: 1830 | C31: =IFERROR(VLOOKUP(B31,차량리스트!$A:$C,2,0),"") -> K5 | D31: =IFERROR(VLOOKUP(B31,차량리스트!$A:$C,3,0),"") -> 45966 | M31: m
A32: 46240 | B32: 1832 | C32: =IFERROR(VLOOKUP(B32,차량리스트!$A:$C,2,0),"") -> K5H | D32: =IFERROR(VLOOKUP(B32,차량리스트!$A:$C,3,0),"") -> 44609 | M32: m
C33: =IFERROR(VLOOKUP(B33,차량리스트!$A:$C,2,0),"") | D33: =IFERROR(VLOOKUP(B33,차량리스트!$A:$C,3,0),"")
C34: =IFERROR(VLOOKUP(B34,차량리스트!$A:$C,2,0),"") | D34: =IFERROR(VLOOKUP(B34,차량리스트!$A:$C,3,0),"")
C35: =IFERROR(VLOOKUP(B35,차량리스트!$A:$C,2,0),"") | D35: =IFERROR(VLOOKUP(B35,차량리스트!$A:$C,3,0),"")
C36: =IFERROR(VLOOKUP(B36,차량리스트!$A:$C,2,0),"") | D36: =IFERROR(VLOOKUP(B36,차량리스트!$A:$C,3,0),"")
C37: =IFERROR(VLOOKUP(B37,차량리스트!$A:$C,2,0),"") | D37: =IFERROR(VLOOKUP(B37,차량리스트!$A:$C,3,0),"")
C38: =IFERROR(VLOOKUP(B38,차량리스트!$A:$C,2,0),"") | D38: =IFERROR(VLOOKUP(B38,차량리스트!$A:$C,3,0),"")
C39: =IFERROR(VLOOKUP(B39,차량리스트!$A:$C,2,0),"") | D39: =IFERROR(VLOOKUP(B39,차량리스트!$A:$C,3,0),"")
C40: =IFERROR(VLOOKUP(B40,차량리스트!$A:$C,2,0),"") | D40: =IFERROR(VLOOKUP(B40,차량리스트!$A:$C,3,0),"")
...

Sheet 9월
A1: 정비일 | B1: 차번 | C1: 차종 | D1: 등록일자 | E1: 예방정비 | F1: 일반정비 | G1: 사고수리 | H1: 검사 | I1: 엔진오일(L) | J1: 미션오일(L) | K1: 타이어_교체 | L1: 타이어_펑크 | M1: 명일_정비예정 | N1: 기타사항
C2: =IFERROR(VLOOKUP(B2,차량리스트!$A:$C,2,0),"") | D2: =IFERROR(VLOOKUP(B2,차량리스트!$A:$C,3,0),"")
C3: =IFERROR(VLOOKUP(B3,차량리스트!$A:$C,2,0),"") | D3: =IFERROR(VLOOKUP(B3,차량리스트!$A:$C,3,0),"")
C4: =IFERROR(VLOOKUP(B4,차량리스트!$A:$C,2,0),"") | D4: =IFERROR(VLOOKUP(B4,차량리스트!$A:$C,3,0),"")
C5: =IFERROR(VLOOKUP(B5,차량리스트!$A:$C,2,0),"") | D5: =IFERROR(VLOOKUP(B5,차량리스트!$A:$C,3,0),"")
C6: =IFERROR(VLOOKUP(B6,차량리스트!$A:$C,2,0),"") | D6: =IFERROR(VLOOKUP(B6,차량리스트!$A:$C,3,0),"")
C7: =IFERROR(VLOOKUP(B7,차량리스트!$A:$C,2,0),"") | D7: =IFERROR(VLOOKUP(B7,차량리스트!$A:$C,3,0),"")
C8: =IFERROR(VLOOKUP(B8,차량리스트!$A:$C,2,0),"") | D8: =IFERROR(VLOOKUP(B8,차량리스트!$A:$C,3,0),"")
C9: =IFERROR(VLOOKUP(B9,차량리스트!$A:$C,2,0),"") | D9: =IFERROR(VLOOKUP(B9,차량리스트!$A:$C,3,0),"")
C10: =IFERROR(VLOOKUP(B10,차량리스트!$A:$C,2,0),"") | D10: =IFERROR(VLOOKUP(B10,차량리스트!$A:$C,3,0),"")
C11: =IFERROR(VLOOKUP(B11,차량리스트!$A:$C,2,0),"") | D11: =IFERROR(VLOOKUP(B11,차량리스트!$A:$C,3,0),"")
C12: =IFERROR(VLOOKUP(B12,차량리스트!$A:$C,2,0),"") | D12: =IFERROR(VLOOKUP(B12,차량리스트!$A:$C,3,0),"")
C13: =IFERROR(VLOOKUP(B13,차량리스트!$A:$C,2,0),"") | D13: =IFERROR(VLOOKUP(B13,차량리스트!$A:$C,3,0),"")
... C101: =IFERROR(VLOOKUP(B101,차량리스트!$A:$C,2,0),"") | D101: =IFERROR(VLOOKUP(B101,차량리스트!$A:$C,3,0),"")

Sheet 10월
A1: 정비일 | B1: 차번 | C1: 차종 | D1: 등록일자 | E1: 예방정비 | F1: 일반정비 | G1: 사고수리 | H1: 검사 | I1: 엔진오일(L) | J1: 미션오일(L) | K1: 타이어_교체 | L1: 타이어_펑크 | M1: 명일_정비예정 | N1: 기타사항
C2: =IFERROR(VLOOKUP(B2,차량리스트!$A:$C,2,0),"") | D2: =IFERROR(VLOOKUP(B2,차량리스트!$A:$C,3,0),"")
C3: =IFERROR(VLOOKUP(B3,차량리스트!$A:$C,2,0),"") | D3: =IFERROR(VLOOKUP(B3,차량리스트!$A:$C,3,0),"")
C4: =IFERROR(VLOOKUP(B4,차량리스트!$A:$C,2,0),"") | D4: =IFERROR(VLOOKUP(B4,차량리스트!$A:$C,3,0),"")
C5: =IFERROR(VLOOKUP(B5,차량리스트!$A:$C,2,0),"") | D5: =IFERROR(VLOOKUP(B5,차량리스트!$A:$C,3,0),"")
C6: =IFERROR(VLOOKUP(B6,차량리스트!$A:$C,2,0),"") | D6: =IFERROR(VLOOKUP(B6,차량리스트!$A:$C,3,0),"")
C7: =IFERROR(VLOOKUP(B7,차량리스트!$A:$C,2,0),"") | D7: =IFERROR(VLOOKUP(B7,차량리스트!$A:$C,3,0),"")
C8: =IFERROR(VLOOKUP(B8,차량리스트!$A:$C,2,0),"") | D8: =IFERROR(VLOOKUP(B8,차량리스트!$A:$C,3,0),"")
C9: =IFERROR(VLOOKUP(B9,차량리스트!$A:$C,2,0),"") | D9: =IFERROR(VLOOKUP(B9,차량리스트!$A:$C,3,0),"")
C10: =IFERROR(VLOOKUP(B10,차량리스트!$A:$C,2,0),"") | D10: =IFERROR(VLOOKUP(B10,차량리스트!$A:$C,3,0),"")
C11: =IFERROR(VLOOKUP(B11,차량리스트!$A:$C,2,0),"") | D11: =IFERROR(VLOOKUP(B11,차량리스트!$A:$C,3,0),"")
C12: =IFERROR(VLOOKUP(B12,차량리스트!$A:$C,2,0),"") | D12: =IFERROR(VLOOKUP(B12,차량리스트!$A:$C,3,0),"")
C13: =IFERROR(VLOOKUP(B13,차량리스트!$A:$C,2,0),"") | D13: =IFERROR(VLOOKUP(B13,차량리스트!$A:$C,3,0),"")
... C101: =IFERROR(VLOOKUP(B101,차량리스트!$A:$C,2,0),"") | D101: =IFERROR(VLOOKUP(B101,차량리스트!$A:$C,3,0),"")

Sheet 11월
A1: 정비일 | B1: 차번 | C1: 차종 | D1: 등록일자 | E1: 예방정비 | F1: 일반정비 | G1: 사고수리 | H1: 검사 | I1: 엔진오일(L) | J1: 미션오일(L) | K1: 타이어_교체 | L1: 타이어_펑크 | M1: 명일_정비예정 | N1: 기타사항
C2: =IFERROR(VLOOKUP(B2,차량리스트!$A:$C,2,0),"") | D2: =IFERROR(VLOOKUP(B2,차량리스트!$A:$C,3,0),"")
C3: =IFERROR(VLOOKUP(B3,차량리스트!$A:$C,2,0),"") | D3: =IFERROR(VLOOKUP(B3,차량리스트!$A:$C,3,0),"")
C4: =IFERROR(VLOOKUP(B4,차량리스트!$A:$C,2,0),"") | D4: =IFERROR(VLOOKUP(B4,차량리스트!$A:$C,3,0),"")
C5: =IFERROR(VLOOKUP(B5,차량리스트!$A:$C,2,0),"") | D5: =IFERROR(VLOOKUP(B5,차량리스트!$A:$C,3,0),"")
C6: =IFERROR(VLOOKUP(B6,차량리스트!$A:$C,2,0),"") | D6: =IFERROR(VLOOKUP(B6,차량리스트!$A:$C,3,0),"")
C7: =IFERROR(VLOOKUP(B7,차량리스트!$A:$C,2,0),"") | D7: =IFERROR(VLOOKUP(B7,차량리스트!$A:$C,3,0),"")
C8: =IFERROR(VLOOKUP(B8,차량리스트!$A:$C,2,0),"") | D8: =IFERROR(VLOOKUP(B8,차량리스트!$A:$C,3,0),"")
C9: =IFERROR(VLOOKUP(B9,차량리스트!$A:$C,2,0),"") | D9: =IFERROR(VLOOKUP(B9,차량리스트!$A:$C,3,0),"")
C10: =IFERROR(VLOOKUP(B10,차량리스트!$A:$C,2,0),"") | D10: =IFERROR(VLOOKUP(B10,차량리스트!$A:$C,3,0),"")
C11: =IFERROR(VLOOKUP(B11,차량리스트!$A:$C,2,0),"") | D11: =IFERROR(VLOOKUP(B11,차량리스트!$A:$C,3,0),"")
C12: =IFERROR(VLOOKUP(B12,차량리스트!$A:$C,2,0),"") | D12: =IFERROR(VLOOKUP(B12,차량리스트!$A:$C,3,0),"")
C13: =IFERROR(VLOOKUP(B13,차량리스트!$A:$C,2,0),"") | D13: =IFERROR(VLOOKUP(B13,차량리스트!$A:$C,3,0),"")
... C101: =IFERROR(VLOOKUP(B101,차량리스트!$A:$C,2,0),"") | D101: =IFERROR(VLOOKUP(B101,차량리스트!$A:$C,3,0),"")

Sheet 12월
A1: 정비일 | B1: 차번 | C1: 차종 | D1: 등록일자 | E1: 예방정비 | F1: 일반정비 | G1: 사고수리 | H1: 검사 | I1: 엔진오일(L) | J1: 미션오일(L) | K1: 타이어_교체 | L1: 타이어_펑크 | M1: 명일_정비예정 | N1: 기타사항
C2: =IFERROR(VLOOKUP(B2,차량리스트!$A:$C,2,0),"") | D2: =IFERROR(VLOOKUP(B2,차량리스트!$A:$C,3,0),"")
C3: =IFERROR(VLOOKUP(B3,차량리스트!$A:$C,2,0),"") | D3: =IFERROR(VLOOKUP(B3,차량리스트!$A:$C,3,0),"")
C4: =IFERROR(VLOOKUP(B4,차량리스트!$A:$C,2,0),"") | D4: =IFERROR(VLOOKUP(B4,차량리스트!$A:$C,3,0),"")
C5: =IFERROR(VLOOKUP(B5,차량리스트!$A:$C,2,0),"") | D5: =IFERROR(VLOOKUP(B5,차량리스트!$A:$C,3,0),"")
C6: =IFERROR(VLOOKUP(B6,차량리스트!$A:$C,2,0),"") | D6: =IFERROR(VLOOKUP(B6,차량리스트!$A:$C,3,0),"")
C7: =IFERROR(VLOOKUP(B7,차량리스트!$A:$C,2,0),"") | D7: =IFERROR(VLOOKUP(B7,차량리스트!$A:$C,3,0),"")
C8: =IFERROR(VLOOKUP(B8,차량리스트!$A:$C,2,0),"") | D8: =IFERROR(VLOOKUP(B8,차량리스트!$A:$C,3,0),"")
C9: =IFERROR(VLOOKUP(B9,차량리스트!$A:$C,2,0),"") | D9: =IFERROR(VLOOKUP(B9,차량리스트!$A:$C,3,0),"")
C10: =IFERROR(VLOOKUP(B10,차량리스트!$A:$C,2,0),"") | D10: =IFERROR(VLOOKUP(B10,차량리스트!$A:$C,3,0),"")
C11: =IFERROR(VLOOKUP(B11,차량리스트!$A:$C,2,0),"") | D11: =IFERROR(VLOOKUP(B11,차량리스트!$A:$C,3,0),"")
C12: =IFERROR(VLOOKUP(B12,차량리스트!$A:$C,2,0),"") | D12: =IFERROR(VLOOKUP(B12,차량리스트!$A:$C,3,0),"")
C13: =IFERROR(VLOOKUP(B13,차량리스트!$A:$C,2,0),"") | D13: =IFERROR(VLOOKUP(B13,차량리스트!$A:$C,3,0),"")
... C101: =IFERROR(VLOOKUP(B101,차량리스트!$A:$C,2,0),"") | D101: =IFERROR(VLOOKUP(B101,차량리스트!$A:$C,3,0),"")

Sheet 차량리스트
A1: 차번 | B1: 차종 | C1: 등록일자
A2: 1801 | B2: K5 | C2: 45966
A3: 1802 | C3: 말소
A4: 1803 | B4: K5H | C4: 44566
A5: 1804 | B5: K5 | C5: 45873
A6: 1805 | C6: 말소
A7: 1807 | B7: K5H | C7: 44288
A8: 1808 | C8: 말소
A9: 1809 | B9: 아닉 | C9: 45615
A10: 1810 | C10: 말소
A11: 1812 | B11: 아닉 | C11: 45594
A12: 1813 | B12: K5H | C12: 45166
A13: 1814 | B13: 쏘타 | C13: 45626
A14: 1815 | B14: 쏘타 | C14: 45626
A15: 1816 | C15: 말소
A16: 1817 | C16: 말소
A17: 1818 | C17: 말소
A18: 1819 | B18: K5 | C18: 45873
A19: 1820 | C19: 말소
A20: 1821 | C20: 말소
A21: 1823 | B21: K5 | C21: 45455
A22: 1825 | B22: 쏘타 | C22: 45626
A23: 1826 | B23: 니로 | C23: 44802
A24: 1827 | C24: 말소
A25: 1828 | B25: K5H | C25: 44566
A26: 1829 | C26: 말소
A27: 1830 | B27: K5 | C27: 45966
A28: 1832 | B28: K5H | C28: 44609
A29: 1833 | B29: K5 | C29: 45904
A30: 1834 | C30: 말소
A31: 1835 | B31: 아닉 | C31: 45547
A32: 1836 | B32: 쏘타 | C32: 45931
A33: 1838 | C33: 말소
A34: 1839 | B34: 니로 | C34: 44802
A35: 1840 | B35: K5 | C35: 45477
A36: 1842 | B36: 아닉 | C36: 45594
A37: 1843 | B37: K5 | C37: 45974
A38: 1844 | B38: 니로 | C38: 2022-08.04
A39: 1845 | C39: 말소
A40: 1847 | B40: 아닉 | C40: 45534
...
